Workbook
Name _04_7065: #REF!
Name Code: #REF!
Name Code6: #REF!
Name DATA: #REF!
Name Focus: #REF!
Name PN: #REF!
Name PN_Description: #REF!
Name PT_EndRow: COUNTA(#REF!)+PT_StartRow-3
Name PT_EndRow: COUNTA(#REF!)+PT_StartRow-3
Name PT_StartRow: ROW(INDEX(#REF!,MATCH("*",#REF!,0),1))+1
Name ชื่อสาขา: #REF!
Name ชื่อสินค้า: #REF!
Name ยอดขาย: #REF!

Sheet EXC.VAT-ไม่รวม VAT Thomas
A1: Commission & Outlet Rebate Calculation Form
A2: Outlet :
A3: BDE : | D3: Types & Sub Types :
A4: Period : | D4: Area :
A5: Supervisor : | D5: Agent :
G6: ACTUAL OFF TAKE | J6: TOTAL ACTUAL OFF TAKE VALUE
A7: Principle | B7: Category | C7: Brand | D7: Product | E7: Size | F7: Packing | G7: Price INC.VAT | H7: Price EXC.VAT | I7: Vol. Btls. | J7: Total Price Inc.VAT | K7: Total Price Exc.VAT | L7: Rebate % | M7: Rebate Value
A8: TEG | B8: Single Malt Scotch | C8: The Macallan | D8: The Macallan Sherry Oak 12YO | E8: 700ml | F8: 12 | G8: =H8*1.07 -> 0 | J8: =G8*I8 -> 0 | K8: =H8*I8 -> 0 | M8: =K8*L8 -> 0
A9: TEG | B9: Single Malt Scotch | C9: The Macallan | D9: The Macallan Triple Cask 12YO | E9: 700ml | F9: 12 | G9: =H9*1.07 -> 0 | J9: =G9*I9 -> 0 | K9: =H9*I9 -> 0 | M9: =K9*L9 -> 0
A10: TEG | B10: Single Malt Scotch | C10: The Macallan | D10: The Macallan Double Cask 12YO | E10: 700ml | F10: 12 | G10: =H10*1.07 -> 0 | J10: =G10*I10 -> 0 | K10: =H10*I10 -> 0 | M10: =K10*L10 -> 0
A11: TEG | B11: Single Malt Scotch | C11: The Macallan | D11: The Macallan Double Cask 15YO | E11: 700ml | F11: 6 | G11: =H11*1.07 -> 0 | J11: =G11*I11 -> 0 | K11: =H11*I11 -> 0 | M11: =K11*L11 -> 0
A12: TEG | B12: Single Malt Scotch | C12: The Macallan | D12: The Macallan Triple Cask 15YO | E12: 700ml | F12: 6 | G12: =H12*1.07 -> 0 | J12: =G12*I12 -> 0 | K12: =H12*I12 -> 0 | M12: =K12*L12 -> 0
A13: TEG | B13: Single Malt Scotch | C13: The Macallan | D13: The Macalan Double Cask 18YO | E13: 700ml | F13: 6 | G13: =H13*1.07 -> 0 | J13: =G13*I13 -> 0 | K13: =H13*I13 -> 0 | M13: =K13*L13 -> 0
A14: TEG | B14: Single Malt Scotch | C14: The Macallan | D14: The Macallan Sherry Oak 18YO | E14: 700ml | F14: 6 | G14: =H14*1.07 -> 0 | J14: =G14*I14 -> 0 | K14: =H14*I14 -> 0 | M14: =K14*L14 -> 0
A15: TEG | B15: Single Malt Scotch | C15: The Macallan | D15: The Macallan Sherry Oak 25YO | E15: 700ml | F15: 3 | G15: =H15*1.07 -> 0 | J15: =G15*I15 -> 0 | K15: =H15*I15 -> 0 | M15: =K15*L15 -> 0
A16: TEG | B16: Single Malt Scotch | C16: The Macallan | D16: The Macallan Harmony Collection | E16: 700ml | F16: 6 | G16: =H16*1.07 -> 0 | J16: =G16*I16 -> 0 | K16: =H16*I16 -> 0 | M16: =K16*L16 -> 0
A17: TEG | B17: Single Malt Scotch | C17: The Macallan | D17: The Macallan Rare Cask | E17: 700ml | F17: 3 | G17: =H17*1.07 -> 0 | J17: =G17*I17 -> 0 | K17: =H17*I17 -> 0 | M17: =K17*L17 -> 0
A18: TEG | B18: Single Malt Scotch | C18: The Macallan | D18: The Macallan Reflexion | E18: 700ml | F18: 2 | G18: =H18*1.07 -> 0 | J18: =G18*I18 -> 0 | K18: =H18*I18 -> 0 | M18: =K18*L18 -> 0
A19: TEG | B19: Single Malt Scotch | C19: The Macallan | D19: The Macallan Classic Cut Whisky | E19: 700ml | F19: 12 | G19: =H19*1.07 -> 0 | J19: =G19*I19 -> 0 | K19: =H19*I19 -> 0 | M19: =K19*L19 -> 0
... A59: Campari | B59: American Whiskey | C59: Wild Turkey | D59: Russell's Reserve 10YO | E59: 750ml | F59: 6 | G59: =H59*1.07 -> 0 | J59: =G59*I59 -> 0 | K59: =H59*I59 -> 0 | M59: =K59*L59 -> 0
A60: Campari | B60: American Whiskey | C60: Wild Turkey | D60: Wild Turkey Forgiven | E60: 750ml | G60: =H60*1.07 -> 0 | J60: =G60*I60 -> 0 | K60: =H60*I60 -> 0 | M60: =K60*L60 -> 0
A61: Campari | B61: American Whiskey | C61: Wild Turkey | D61: Wild Turkey Masters 17YO | E61: 750ml | F61: 6 | G61: =H61*1.07 -> 0 | J61: =G61*I61 -> 0 | K61: =H61*I61 -> 0 | M61: =K61*L61 -> 0
A62: Campari | B62: American Whiskey | C62: Wild Turkey | D62: Wild Turkey American Honey 35.5% | E62: 750ml | F62: 12 | G62: =H62*1.07 -> 0 | J62: =G62*I62 -> 0 | K62: =H62*I62 -> 0 | M62: =K62*L62 -> 0
A63: Independent | B63: Japanese Whiskey | C63: Kyoto | D63: Kyoto Whisky Aka Obi | E63: 700ml | F63: 12 | G63: =H63*1.07 -> 0 | J63: =G63*I63 -> 0 | K63: =H63*I63 -> 0 | M63: =K63*L63 -> 0
A64: Independent | B64: Japanese Whiskey | C64: Kyoto | D64: Kyoto Whisky Murasaki-Obi | E64: 700ml | F64: 12 | G64: =H64*1.07 -> 0 | J64: =G64*I64 -> 0 | K64: =H64*I64 -> 0 | M64: =K64*L64 -> 0
A65: Independent | B65: Japanese Whiskey | C65: Kyoto | D65: Kyoto Whisky Kuro-Obi | E65: 700ml | F65: 12 | G65: =H65*1.07 -> 0 | J65: =G65*I65 -> 0 | K65: =H65*I65 -> 0 | M65: =K65*L65 -> 0
A66: Campari | B66: Cachaca | C66: Sagatiba | D66: Sagatiba Cachaca | E66: 700ml | F66: 6 | G66: =H66*1.07 -> 0 | J66: =G66*I66 -> 0 | K66: =H66*I66 -> 0 | M66: =K66*L66 -> 0
A67: Campari | B67: RUM | C67: Appleton | D67: Appleton White Jamaican | E67: 750ml | F67: 12 | G67: =H67*1.07 -> 0 | J67: =G67*I67 -> 0 | K67: =H67*I67 -> 0 | M67: =K67*L67 -> 0
A68: Campari | B68: RUM | C68: Appleton | D68: Appleton Special Dark Jamaican | E68: 750ml | F68: 12 | G68: =H68*1.07 -> 0 | J68: =G68*I68 -> 0 | K68: =H68*I68 -> 0 | M68: =K68*L68 -> 0
A69: Campari | B69: RUM | C69: Appleton | D69: Appleton VX Jamaican | E69: 750ml | G69: =H69*1.07 -> 0 | J69: =G69*I69 -> 0 | K69: =H69*I69 -> 0 | M69: =K69*L69 -> 0
A70: Campari | B70: RUM | C70: Appleton | D70: Appleton Estate Reserve Jamaican | E70: 750ml | F70: 12 | G70: =H70*1.07 -> 0 | J70: =G70*I70 -> 0 | K70: =H70*I70 -> 0 | M70: =K70*L70 -> 0
A71: Campari | B71: RUM | C71: Appleton | D71: Appleton Estate Signature Jamaican Blend | E71: 750ml | F71: 12 | G71: =H71*1.07 -> 0 | J71: =G71*I71 -> 0 | K71: =H71*I71 -> 0 | M71: =K71*L71 -> 0
A72: Campari | B72: RUM | C72: Appleton | D72: Appleton Estate 12YO Rare Cask | E72: 750ml | F72: 12 | G72: =H72*1.07 -> 0 | J72: =G72*I72 -> 0 | K72: =H72*I72 -> 0 | M72: =K72*L72 -> 0
A73: Campari | B73: RUM | C73: Appleton | D73: Appleton Estate 21YO Jamaican | E73: 750ml | F73: 6 | G73: =H73*1.07 -> 0 | J73: =G73*I73 -> 0 | K73: =H73*I73 -> 0 | M73: =K73*L73 -> 0
A74: Campari | B74: RUM | C74: Appleton | D74: Appleton Estate 30YO Jamaican | E74: 750ml | F74: 6 | G74: =H74*1.07 -> 0 | J74: =G74*I74 -> 0 | K74: =H74*I74 -> 0 | M74: =K74*L74 -> 0
A75: Campari | B75: RUM | C75: Kingston | D75: Kingston 62 Jamaica Gold Rum | E75: 750ml | F75: 12 | G75: =H75*1.07 -> 0 | J75: =G75*I75 -> 0 | K75: =H75*I75 -> 0 | M75: =K75*L75 -> 0
A76: RC | B76: RUM | C76: Mt Gay | D76: Mt Gay Eclipse Barbados | E76: 700ml | F76: 6 | G76: =H76*1.07 -> 0 | J76: =G76*I76 -> 0 | K76: =H76*I76 -> 0 | M76: =K76*L76 -> 0
A77: RC | B77: RUM | C77: Mt Gay | D77: Mt Gay Black Barrel Barbados | E77: 700ml | F77: 6 | G77: =H77*1.07 -> 0 | J77: =G77*I77 -> 0 | K77: =H77*I77 -> 0 | M77: =K77*L77 -> 0
A78: RC | B78: RUM | C78: Mt Gay | D78: Mt Gay XO Barbados | E78: 700ml | F78: 6 | G78: =H78*1.07 -> 0 | J78: =G78*I78 -> 0 | K78: =H78*I78 -> 0 | M78: =K78*L78 -> 0
A79: TEG | B79: RUM | C79: Brugal | D79: Brugal Blanco Supremo White Rum | E79: 700ml | F79: 12 | G79: =H79*1.07 -> 0 | J79: =G79*I79 -> 0 | K79: =H79*I79 -> 0 | M79: =K79*L79 -> 0
...

Sheet INC.VAT-รวม VAT Thomas
A1: Commission & Outlet Rebate Calculation Form
A2: Outlet :
A3: BDE : | D3: Types & Sub Types :
A4: Period : | D4: Area :
A5: Supervisor : | D5: Agent :
G6: ACTUAL OFF TAKE | J6: TOTAL ACTUAL OFF TAKE VALUE
A7: Principle | B7: Category | C7: Brand | D7: Product | E7: Size | F7: Packing | G7: Price INC.VAT | H7: Price EXC.VAT | I7: Vol. Btls. | J7: Total Price Inc.VAT | K7: Total Price Exc.VAT | L7: Rebate % | M7: Rebate Value
A8: TEG | B8: Single Malt Scotch | C8: The Macallan | D8: The Macallan Sherry Oak 12YO | E8: 700ml | F8: 12 | H8: =G8/1.07 -> 0 | J8: =G8*I8 -> 0 | K8: =H8*I8 -> 0 | M8: =K8*L8 -> 0
A9: TEG | B9: Single Malt Scotch | C9: The Macallan | D9: The Macallan Triple Cask 12YO | E9: 700ml | F9: 12 | H9: =G9/1.07 -> 0 | J9: =G9*I9 -> 0 | K9: =H9*I9 -> 0 | M9: =K9*L9 -> 0
A10: TEG | B10: Single Malt Scotch | C10: The Macallan | D10: The Macallan Double Cask 12YO | E10: 700ml | F10: 12 | H10: =G10/1.07 -> 0 | J10: =G10*I10 -> 0 | K10: =H10*I10 -> 0 | M10: =K10*L10 -> 0
A11: TEG | B11: Single Malt Scotch | C11: The Macallan | D11: The Macallan Double Cask 15YO | E11: 700ml | F11: 6 | H11: =G11/1.07 -> 0 | J11: =G11*I11 -> 0 | K11: =H11*I11 -> 0 | M11: =K11*L11 -> 0
A12: TEG | B12: Single Malt Scotch | C12: The Macallan | D12: The Macallan Triple Cask 15YO | E12: 700ml | F12: 6 | H12: =G12/1.07 -> 0 | J12: =G12*I12 -> 0 | K12: =H12*I12 -> 0 | M12: =K12*L12 -> 0
A13: TEG | B13: Single Malt Scotch | C13: The Macallan | D13: The Macalan Double Cask 18YO | E13: 700ml | F13: 6 | H13: =G13/1.07 -> 0 | J13: =G13*I13 -> 0 | K13: =H13*I13 -> 0 | M13: =K13*L13 -> 0
A14: TEG | B14: Single Malt Scotch | C14: The Macallan | D14: The Macallan Sherry Oak 18YO | E14: 700ml | F14: 6 | H14: =G14/1.07 -> 0 | J14: =G14*I14 -> 0 | K14: =H14*I14 -> 0 | M14: =K14*L14 -> 0
A15: TEG | B15: Single Malt Scotch | C15: The Macallan | D15: The Macallan Sherry Oak 25YO | E15: 700ml | F15: 3 | H15: =G15/1.07 -> 0 | J15: =G15*I15 -> 0 | K15: =H15*I15 -> 0 | M15: =K15*L15 -> 0
A16: TEG | B16: Single Malt Scotch | C16: The Macallan | D16: The Macallan Harmony Collection | E16: 700ml | F16: 6 | H16: =G16/1.07 -> 0 | J16: =G16*I16 -> 0 | K16: =H16*I16 -> 0 | M16: =K16*L16 -> 0
A17: TEG | B17: Single Malt Scotch | C17: The Macallan | D17: The Macallan Rare Cask | E17: 700ml | F17: 3 | H17: =G17/1.07 -> 0 | J17: =G17*I17 -> 0 | K17: =H17*I17 -> 0 | M17: =K17*L17 -> 0
A18: TEG | B18: Single Malt Scotch | C18: The Macallan | D18: The Macallan Reflexion | E18: 700ml | F18: 2 | H18: =G18/1.07 -> 0 | J18: =G18*I18 -> 0 | K18: =H18*I18 -> 0 | M18: =K18*L18 -> 0
A19: TEG | B19: Single Malt Scotch | C19: The Macallan | D19: The Macallan Classic Cut Whisky | E19: 700ml | F19: 12 | H19: =G19/1.07 -> 0 | J19: =G19*I19 -> 0 | K19: =H19*I19 -> 0 | M19: =K19*L19 -> 0
... A59: Campari | B59: American Whiskey | C59: Wild Turkey | D59: Russell's Reserve 10YO | E59: 750ml | F59: 6 | H59: =G59/1.07 -> 0 | J59: =G59*I59 -> 0 | K59: =H59*I59 -> 0 | M59: =K59*L59 -> 0
A60: Campari | B60: American Whiskey | C60: Wild Turkey | D60: Wild Turkey Forgiven | E60: 750ml | H60: =G60/1.07 -> 0 | J60: =G60*I60 -> 0 | K60: =H60*I60 -> 0 | M60: =K60*L60 -> 0
A61: Campari | B61: American Whiskey | C61: Wild Turkey | D61: Wild Turkey Masters 17YO | E61: 750ml | F61: 6 | H61: =G61/1.07 -> 0 | J61: =G61*I61 -> 0 | K61: =H61*I61 -> 0 | M61: =K61*L61 -> 0
A62: Campari | B62: American Whiskey | C62: Wild Turkey | D62: Wild Turkey American Honey 35.5% | E62: 750ml | F62: 12 | H62: =G62/1.07 -> 0 | J62: =G62*I62 -> 0 | K62: =H62*I62 -> 0 | M62: =K62*L62 -> 0
A63: Independent | B63: Japanese Whiskey | C63: Kyoto | D63: Kyoto Whisky Aka Obi | E63: 700ml | F63: 12 | H63: =G63/1.07 -> 0 | J63: =G63*I63 -> 0 | K63: =H63*I63 -> 0 | M63: =K63*L63 -> 0
A64: Independent | B64: Japanese Whiskey | C64: Kyoto | D64: Kyoto Whisky Murasaki-Obi | E64: 700ml | F64: 12 | H64: =G64/1.07 -> 0 | J64: =G64*I64 -> 0 | K64: =H64*I64 -> 0 | M64: =K64*L64 -> 0
A65: Independent | B65: Japanese Whiskey | C65: Kyoto | D65: Kyoto Whisky Kuro-Obi | E65: 700ml | F65: 12 | H65: =G65/1.07 -> 0 | J65: =G65*I65 -> 0 | K65: =H65*I65 -> 0 | M65: =K65*L65 -> 0
A66: Campari | B66: Cachaca | C66: Sagatiba | D66: Sagatiba Cachaca | E66: 700ml | F66: 6 | H66: =G66/1.07 -> 0 | J66: =G66*I66 -> 0 | K66: =H66*I66 -> 0 | M66: =K66*L66 -> 0
A67: Campari | B67: RUM | C67: Appleton | D67: Appleton White Jamaican | E67: 750ml | F67: 12 | H67: =G67/1.07 -> 0 | J67: =G67*I67 -> 0 | K67: =H67*I67 -> 0 | M67: =K67*L67 -> 0
A68: Campari | B68: RUM | C68: Appleton | D68: Appleton Special Dark Jamaican | E68: 750ml | F68: 12 | H68: =G68/1.07 -> 0 | J68: =G68*I68 -> 0 | K68: =H68*I68 -> 0 | M68: =K68*L68 -> 0
A69: Campari | B69: RUM | C69: Appleton | D69: Appleton VX Jamaican | E69: 750ml | H69: =G69/1.07 -> 0 | J69: =G69*I69 -> 0 | K69: =H69*I69 -> 0 | M69: =K69*L69 -> 0
A70: Campari | B70: RUM | C70: Appleton | D70: Appleton Estate Reserve Jamaican | E70: 750ml | F70: 12 | H70: =G70/1.07 -> 0 | J70: =G70*I70 -> 0 | K70: =H70*I70 -> 0 | M70: =K70*L70 -> 0
A71: Campari | B71: RUM | C71: Appleton | D71: Appleton Estate Signature Jamaican Blend | E71: 750ml | F71: 12 | H71: =G71/1.07 -> 0 | J71: =G71*I71 -> 0 | K71: =H71*I71 -> 0 | M71: =K71*L71 -> 0
A72: Campari | B72: RUM | C72: Appleton | D72: Appleton Estate 12YO Rare Cask | E72: 750ml | F72: 12 | H72: =G72/1.07 -> 0 | J72: =G72*I72 -> 0 | K72: =H72*I72 -> 0 | M72: =K72*L72 -> 0
A73: Campari | B73: RUM | C73: Appleton | D73: Appleton Estate 21YO Jamaican | E73: 750ml | F73: 6 | H73: =G73/1.07 -> 0 | J73: =G73*I73 -> 0 | K73: =H73*I73 -> 0 | M73: =K73*L73 -> 0
A74: Campari | B74: RUM | C74: Appleton | D74: Appleton Estate 30YO Jamaican | E74: 750ml | F74: 6 | H74: =G74/1.07 -> 0 | J74: =G74*I74 -> 0 | K74: =H74*I74 -> 0 | M74: =K74*L74 -> 0
A75: Campari | B75: RUM | C75: Kingston | D75: Kingston 62 Jamaica Gold Rum | E75: 750ml | F75: 12 | H75: =G75/1.07 -> 0 | J75: =G75*I75 -> 0 | K75: =H75*I75 -> 0 | M75: =K75*L75 -> 0
A76: RC | B76: RUM | C76: Mt Gay | D76: Mt Gay Eclipse Barbados | E76: 700ml | F76: 6 | H76: =G76/1.07 -> 0 | J76: =G76*I76 -> 0 | K76: =H76*I76 -> 0 | M76: =K76*L76 -> 0
A77: RC | B77: RUM | C77: Mt Gay | D77: Mt Gay Black Barrel Barbados | E77: 700ml | F77: 6 | H77: =G77/1.07 -> 0 | J77: =G77*I77 -> 0 | K77: =H77*I77 -> 0 | M77: =K77*L77 -> 0
A78: RC | B78: RUM | C78: Mt Gay | D78: Mt Gay XO Barbados | E78: 700ml | F78: 6 | H78: =G78/1.07 -> 0 | J78: =G78*I78 -> 0 | K78: =H78*I78 -> 0 | M78: =K78*L78 -> 0
A79: TEG | B79: RUM | C79: Brugal | D79: Brugal Blanco Supremo White Rum | E79: 700ml | F79: 12 | H79: =G79/1.07 -> 0 | J79: =G79*I79 -> 0 | K79: =H79*I79 -> 0 | M79: =K79*L79 -> 0
...

Sheet INDEX
A1: Input data in yellow cell | G1: Instruction how to use this file | U1: DO NOT DELETE
B3: Outlet Name: | C3: Outlet Name | H3: Step 1.1 | I3: Go to "INDEX" tab. Input outlet data
I4: information about that outlet the outlet name, contract period, and other info are mapped to link with all the monthly sheet
B5: Legal Name: | C5: Outlet Company Limited | V5: Start Month | W5: End Month | Y5: Principle | AA5: Item | AB5: Description | AC5: Code | AD5: Pack | AE5: Size | AF5: Price Update 1 Aug 26 (Direct Ex.VAT
C6: (Please input in English. Go to website DBD to check Enghlish name) | V6: 45292 | W6: 46053 | Y6: ALL | AA6: 1 | AB6: SKYY VODKA ICE BUCKET | AC6: 00-3LICE-BUCKET00
B7: BDE: | C7: Name of BDE | V7: 45323 | W7: 46081 | Y7: TEG | AA7: 2 | AB7: แก้ว APEROL | AC7: 00-GLASS-APEROL00
V8: 45352 | W8: 46112 | Y8: RC | AA8: 3 | AB8: แก้ว CINZANO | AC8: 00-GLASS-CINZANO0
B9: Area: | C9: Area | V9: 45383 | W9: 46142 | Y9: Campari | AA9: 4 | AB9: BOLS SILVER TOP GIN | AC9: 01-SPGIN-07003727 | AD9: 6 | AE9: 700 | AF9: 462
V10: 45413 | W10: 46173 | Y10: Proximo | AA10: 5 | AB10: BOLS GENEVER | AC10: 01-SPGIN-07008005 | AD10: 6 | AE10: 700 | AF10: 2500
B11: Agent: | C11: Agent name | V11: 45444 | W11: 46203 | Y11: Independent | AA11: 6 | AB11: BOLS BROWN CREAM LIQUEUR | AC11: 01-SPLIQ-07002551 | AD11: 6 | AE11: 700 | AF11: 730
V12: 45474 | W12: 46234 | Y12: Lucas Bols | AA12: 7 | AB12: BOLS ELDERFLOWER | AC12: 01-SPLIQ-07002897 | AD12: 6 | AE12: 700 | AF12: 730
B13: Manager: | C13: Manager Name | V13: 45505 | W13: 46265 | AA13: 8 | AB13: BOLS TRIPLE SEC | AC13: 01-SPLIQ-07002941 | AD13: 6 | AE13: 700 | AF13: 730
V14: 45536 | W14: 46295 | AA14: 9 | AB14: BOLS AMARETTO | AC14: 01-SPLIQ-07006625 | AD14: 6 | AE14: 700 | AF14: 730
B15: Contract Start | C15: 46023 | V15: 45566 | W15: 46326 | AA15: 10 | AB15: BOLS APRICOT BRANDY | AC15: 01-SPLIQ-07006632 | AD15: 6 | AE15: 700 | AF15: 730
V16: 45597 | W16: 46356 | AA16: 11 | AB16: BOLS BLUE CURACAO | AC16: 01-SPLIQ-07006656 | AD16: 6 | AE16: 700 | AF16: 730
B17: Contract End | C17: 46387 | H17: Step 1.2 | I17: Go to "Mapping" tab. Input %Rebate for each SKU | V17: 45627 | W17: 46387 | AA17: 12 | AB17: BOLS CHERRY BRANDY | AC17: 01-SPLIQ-07006663 | AD17: 6 | AE17: 700 | AF17: 730
I18: The Rebate% will reflect in all monthly sheet | V18: 45658 | W18: 46418 | AA18: 13 | AB18: BOLS BANANA | AC18: 01-SPLIQ-07006694 | AD18: 6 | AE18: 700 | AF18: 730
B19: Contract Period | C19: =_xlfn.CONCAT(TEXT(C15, "dd mmm yy"), " - ", TEXT(C17, "dd mmm yy")) -> 01 Jan 26 - 31 Dec 26 | V19: 45689 | W19: 46446 | AA19: 14 | AB19: BOLS CREME DE CASSIS | AC19: 01-SPLIQ-07006700 | AD19: 6 | AE19: 700 | AF19: 730
V20: 45717 | W20: 46477 | AA20: 15 | AB20: BOLS CACAO BROWN | AC20: 01-SPLIQ-07006717 | AD20: 6 | AE20: 700 | AF20: 730
B21: Contract Type | C21: Marketing Contract & Yearly Contract | V21: 45748 | W21: 46507 | AA21: 16 | AB21: BOLS CACAO WHITE | AC21: 01-SPLIQ-07006724 | AD21: 6 | AE21: 700 | AF21: 730
V22: 45778 | W22: 46538 | AA22: 17 | AB22: BOLS DRY ORANGE | AC22: 01-SPLIQ-07006731 | AD22: 6 | AE22: 700 | AF22: 730
V23: 45809 | W23: 46568 | AA23: 18 | AB23: BOLS LYCHEE | AC23: 01-SPLIQ-07006786 | AD23: 6 | AE23: 700 | AF23: 730
V24: 45839 | W24: 46599 | AA24: 19 | AB24: BOLS MELON | AC24: 01-SPLIQ-07006809 | AD24: 6 | AE24: 700 | AF24: 730
V25: 45870 | W25: 46630 | AA25: 20 | AB25: BOLS PEACH | AC25: 01-SPLIQ-07006830 | AD25: 6 | AE25: 700 | AF25: 730
V26: 45901 | W26: 46660 | AA26: 21 | AB26: BOLS STRAWBERRY | AC26: 01-SPLIQ-07006885 | AD26: 6 | AE26: 700 | AF26: 730
V27: 45931 | W27: 46691 | AA27: 22 | AB27: BOLS SOUR APPLE | AC27: 01-SPLIQ-07009334 | AD27: 6 | AE27: 700 | AF27: 730
H28: Step 2. | I28: Go to each month tab. There are 3 things to input here | V28: 45962 | W28: 46721 | AA28: 23 | AB28: BOLS PEPPERMINT GREEN | AC28: 01-SPLIQ-07009408 | AD28: 6 | AE28: 700 | AF28: 730
H29: 1. Select the wholesaler based on each skus/invoices | M29: - Total rebate for all principle will show on top right summary | V29: 45992 | W29: 46752 | AA29: 24 | AB29: BOLS VODKA 700 ML. | AC29: 01-SPVOD-07000328 | AD29: 12 | AE29: 700
H30: 2. Input price per bottle : input only 1 column (J or K), which is either with or without VAT | M30: - Selected principle in the dropdown list to see each principle summary | V30: 46023 | W30: 46783 | AA30: 25 | AB30: BOLS VODKA 37.50% | AC30: 01-SPVOD-07008530 | AD30: 6 | AE30: 700 | AF30: 576
H31: 3. Input volume bottles for each skus | V31: 46054 | W31: 46812 | AA31: 26 | AB31: BOLS VODKA 1.0 LITER | AC31: 01-SPVOD-10000311 | AD31: 6 | AE31: 1000
H32: Please note that the wholesaler list is from company's data base. If the customer purchase directly with Alchemy, please select direct sales | V32: 46082 | W32: 46843 | AA32: 27 | AB32: BOLS VODKA 37.5% 1L | AC32: 01-SPVOD-10008547 | AD32: 6 | AE32: 1000 | AF32: 690
H33: For outlets that has an official summary or purchase from the outlet's system and cannot specify the wholesaler, please selet "Outlet Summary" | V33: 46113 | W33: 46873 | AA33: 28 | AB33: GALLIANO ESPRESSO LIQUEUR | AC33: 02-SPLIQ-05001661 | AD33: 6 | AE33: 500 | AF33: 1100
V34: 46143 | W34: 46904 | AA34: 29 | AB34: GALLIANO VANILLA (500 ML) | AC34: 02-SPLIQ-05009501 | AD34: 6 | AE34: 500 | AF34: 1100
V35: 46174 | W35: 46934 | AA35: 30 | AB35: GALLIANO VANILLA | AC35: 02-SPLIQ-07009594 | AD35: 6 | AE35: 700 | AF35: 1520
V36: 46204 | W36: 46965 | AA36: 31 | AB36: HENKES GIN | AC36: 03-SPGIN-07504125 | AD36: 6 | AE36: 750 | AF36: 770
V37: 46235 | W37: 46996 | AA37: 32 | AB37: THE MACALLAN M BLACK SCOTCH WHISKY (2023) | AC37: 04-23MBL-07000168 | AD37: 1 | AE37: 700
V38: 46266 | W38: 47026 | AA38: 33 | AB38: THE MACALLAN M COPPER SCOTCH WHISKY (2023) | AC38: 04-23MCO-07000175 | AD38: 1 | AE38: 700
V39: 46296 | W39: 47057 | AA39: 34 | AB39: THE MACALLAN M SCOTCH WHISKY (2023) | AC39: 04-23MDC-07000151 | AD39: 1 | AE39: 700
V40: 46327 | W40: 47087 | AA40: 35 | AB40: THE MACALLAN A NIGHT ON EARTH SCOTCH WHISKY Y23 | AC40: 04-23WHI-07001806 | AD40: 6 | AE40: 700 | AF40: 7100
V41: 46357 | W41: 47118 | AA41: 36 | AB41: THE MACALLAN HARMONY AMBER MEADOW WHISKY | AC41: 04-23WHI-07002322 | AD41: 12 | AE41: 700 | AF41: 12000
...

Sheet FOC FORM
Q1: Original-Accounting
G2: Alchemy Wines and Spirits (Thailand) Co., Ltd.
A5: FOC FORM
A6: SHOP NAME : | D6: =INDEX!C3 -> Outlet Name | O6: DATE: | P6: 46023
A7: Company/Personal Name : | F7: =INDEX!C5 -> Outlet Company Limited | N7: =IF(F7="","Required","") | O7: Bring out by:- | R7: =IF(O9="","Required","") | U7: https://datawarehouse.dbd.go.th/index
A9: ที่อยู่จัดส่ง : | O9: =INDEX!C7 -> Name of BDE
O10: Type of Investment:
P11: =IF(AND(P12="",P13=""),"Required","")
A12: Delivery Date : | N12: =IF(C12="","Required","") -> Required | P12: x | Q12: Local Generation
A13: Time : | C13: From | D13: 0.47916667 | I13: To | J13: 0.47916667 | N13: =IF(OR(D13="",J13=""),"Required","") | Q13: Brand Owner Investment
A14: ผู้ติดต่อ : | C14: ภาษาไทยเท่านั้น | I14: TEL:
A17: NO. | B17: INVENTORY ID. | G17: NAME | O17: QUANTITY | Q17: UNIT
A18: 1 | B18: 324 | C18: =_xlfn.XLOOKUP(G18,MAPPING!G:G,MAPPING!B:B,"",) -> 01-SPVOD-07008530 | G18: Bols Vodka 700ml | O18: =IF('REBATE TO FOC CALC'!K34="", "", 'REBATE TO FOC CALC'!K34) | Q18: =IF(G18="","-","Bottle") -> Bottle
A19: 2 | C19: =_xlfn.XLOOKUP(G19,MAPPING!G:G,MAPPING!B:B,"",) | G19: =IF('REBATE TO FOC CALC'!E35="", "", 'REBATE TO FOC CALC'!E35) | O19: =IF('REBATE TO FOC CALC'!K35="", "", 'REBATE TO FOC CALC'!K35) | Q19: =IF(G19="","-","Bottle") -> -
A20: 3 | C20: =_xlfn.XLOOKUP(G20,MAPPING!G:G,MAPPING!B:B,"",) | G20: =IF('REBATE TO FOC CALC'!E36="", "", 'REBATE TO FOC CALC'!E36) | O20: =IF('REBATE TO FOC CALC'!K36="", "", 'REBATE TO FOC CALC'!K36) | Q20: =IF(G20="","-","Bottle") -> -
A21: 4 | C21: =_xlfn.XLOOKUP(G21,MAPPING!G:G,MAPPING!B:B,"",) | G21: =IF('REBATE TO FOC CALC'!E37="", "", 'REBATE TO FOC CALC'!E37) | O21: =IF('REBATE TO FOC CALC'!K37="", "", 'REBATE TO FOC CALC'!K37) | Q21: =IF(G21="","-","Bottle") -> -
A22: 5 | C22: =_xlfn.XLOOKUP(G22,MAPPING!G:G,MAPPING!B:B,"",) | G22: =IF('REBATE TO FOC CALC'!E38="", "", 'REBATE TO FOC CALC'!E38) | O22: =IF('REBATE TO FOC CALC'!K38="", "", 'REBATE TO FOC CALC'!K38) | Q22: =IF(G22="","-","Bottle") -> -
A23: 6 | C23: =_xlfn.XLOOKUP(G23,MAPPING!G:G,MAPPING!B:B,"",) | G23: =IF('REBATE TO FOC CALC'!E39="", "", 'REBATE TO FOC CALC'!E39) | O23: =IF('REBATE TO FOC CALC'!K39="", "", 'REBATE TO FOC CALC'!K39) | Q23: =IF(G23="","-","Bottle") -> -
A24: 7 | C24: =_xlfn.XLOOKUP(G24,MAPPING!G:G,MAPPING!B:B,"",) | G24: =IF('REBATE TO FOC CALC'!E40="", "", 'REBATE TO FOC CALC'!E40) | O24: =IF('REBATE TO FOC CALC'!K40="", "", 'REBATE TO FOC CALC'!K40) | Q24: =IF(G24="","-","Bottle") -> -
A25: 8 | C25: =_xlfn.XLOOKUP(G25,MAPPING!G:G,MAPPING!B:B,"",) | G25: =IF('REBATE TO FOC CALC'!E41="", "", 'REBATE TO FOC CALC'!E41) | O25: =IF('REBATE TO FOC CALC'!K41="", "", 'REBATE TO FOC CALC'!K41) | Q25: =IF(G25="","-","Bottle") -> -
A26: 9 | C26: =_xlfn.XLOOKUP(G26,MAPPING!G:G,MAPPING!B:B,"",) | G26: =IF('REBATE TO FOC CALC'!E42="", "", 'REBATE TO FOC CALC'!E42) | O26: =IF('REBATE TO FOC CALC'!K42="", "", 'REBATE TO FOC CALC'!K42) | Q26: =IF(G26="","-","Bottle") -> -
A27: 10 | C27: =_xlfn.XLOOKUP(G27,MAPPING!G:G,MAPPING!B:B,"",) | G27: =IF('REBATE TO FOC CALC'!E43="", "", 'REBATE TO FOC CALC'!E43) | O27: =IF('REBATE TO FOC CALC'!K43="", "", 'REBATE TO FOC CALC'!K43) | Q27: =IF(G27="","-","Bottle") -> -
A28: 11 | C28: =_xlfn.XLOOKUP(G28,MAPPING!G:G,MAPPING!B:B,"",) | G28: =IF('REBATE TO FOC CALC'!E44="", "", 'REBATE TO FOC CALC'!E44) | O28: =IF('REBATE TO FOC CALC'!K44="", "", 'REBATE TO FOC CALC'!K44) | Q28: =IF(G28="","-","Bottle") -> -
A29: 12 | C29: =_xlfn.XLOOKUP(G29,MAPPING!G:G,MAPPING!B:B,"",) | G29: =IF('REBATE TO FOC CALC'!E45="", "", 'REBATE TO FOC CALC'!E45) | O29: =IF('REBATE TO FOC CALC'!K45="", "", 'REBATE TO FOC CALC'!K45) | Q29: =IF(G29="","-","Bottle") -> -
C30: =_xlfn.XLOOKUP(G30,MAPPING!G:G,MAPPING!B:B,"",) | G30: =IF('REBATE TO FOC CALC'!E46="", "", 'REBATE TO FOC CALC'!E46) | O30: =IF('REBATE TO FOC CALC'!K46="", "", 'REBATE TO FOC CALC'!K46)
A31: Detail Of Use : | L31: TOTAL | O31: =SUM(O18:P30) -> 0
A32: Contract Period: | C32: =INDEX!C19 -> 01 Jan 26 - 31 Dec 26
A33: Claim Period:
A34: Promotion:
A35: Reason
A41: Department
A43: Purpose
A44: FALSE | B44: Tasting & Training (06) | G44: FALSE | H44: Sponsorship (08) | K44: FALSE | L44: Event (09) | N44: FALSE | O44: Rebate (11) | Q44: FALSE | R44: PR / Media (12)
A46: FALSE | B46: Borrow | G46: FALSE | H46: Consignment
A49: Requested by | D49: Pay Off By | I49: Mgr.Approved | O49: Marketing Manager
A52: Date ….... / …..... / …..... | D52: Date …….. / ….….. / …….. | I52: Date …….. / ….….. / …….. | O52: Date …….. / ….….. / ……..
A54: =INDEX!C7 -> Name of BDE | D54: (….........................................) | I54: (….........................................) | O54: (….........................................)
A56: ผู้ส่งสินค้า (Delivered by) | I56: ผู้รับสินค้า (For Customer Received by)
A58: …..................................................................................ลงนาม(Please sign here) | I58: …..................................................................................ลงนาม(Please sign here)
A59: ( ) | I59: ( )
...

Sheet CASH REBATE
D7: Request for Rebate Payment
F9: Cheque Date : | G9: X | H9: Payment on 15th.
H10: (Submit document 10 days in advance, cut off on 5th)
H11: Payment on 30th.
H12: (Submit document 10 days in advance, cut off on 20th)
F13: Amount (THB) : | H13: =J36 -> 0
F14: Outlet Name : | H14: =INDEX!C3 -> Outlet Name
F15: Vendor Name : | H15: =INDEX!C5 -> Outlet Company Limited
E18: Contract Period : | G18: =INDEX!C19 -> 01 Jan 26 - 31 Dec 26
E20: Claim Period : | G20: {=IF(COUNTIF(P22:Q32,TRUE)=0,"",TEXT(MIN(IF(P22:P32=TRUE,E22:E32),IF(Q22:Q32=TRUE,I22:I32)),"mmm yy")&IF(COUNTIF(P22:Q32,TRUE)=1,""," - "&TEXT(MAX(IF(P22:P32=TRUE,E22:E32),IF(Q22:Q32=TRUE,I22:I32)),"mmm yy")))}
E22: 46023 | F22: =IF(P22=TRUE,'01'!$T$3,0) -> 0 | I22: 46204 | J22: =IF(Q22=TRUE,'07'!$T$3,0) -> 0 | P22: FALSE | Q22: FALSE
E24: 46054 | F24: =IF(P24=TRUE,'02'!$T$3,0) -> 0 | I24: 46235 | J24: =IF(Q24=TRUE,'08'!$T$3,0) -> 0 | P24: FALSE | Q24: FALSE
E26: 46082 | F26: =IF(P26=TRUE,'03'!$T$3,0) -> 0 | I26: 46266 | J26: =IF(Q26=TRUE,'09'!$T$3,0) -> 0 | P26: FALSE | Q26: FALSE
E28: 46113 | F28: =IF(P28=TRUE,'04'!$T$3,0) -> 0 | I28: 46296 | J28: =IF(Q28=TRUE,'10'!$T$3,0) -> 0 | P28: FALSE | Q28: FALSE
E30: 46143 | F30: =IF(P30=TRUE,'05'!$T$3,0) -> 0 | I30: 46327 | J30: =IF(Q30=TRUE,'11'!$T$3,0) -> 0 | P30: FALSE | Q30: FALSE
E32: 46174 | F32: =IF(P32=TRUE,'06'!$T$3,0) -> 0 | I32: 46357 | J32: =IF(Q32=TRUE,'12'!$T$3,0) -> 0 | P32: FALSE | Q32: FALSE
H36: TOTAL | J36: =SUM(F22:F32,J22:J32) -> 0
F39: BRAND OWNER INVESTMENT | I39: X | J39: LOCAL GENERATION COSTS
F40: (Need Marketing approval)
G42: Bank acc or Promptpay number : | H42: 111-1-11111-1
G44: Bank acc / Promptpay name : | H44: English Name Co., Ltd.
F46: Email : | H46: For sending payment advice (will send to requester email if not specify)
F50: Requested By | I50: Verified By
F52: …..... /…..... / …..... | I52: …..... /…..... / ….....

Sheet REBATE TO FOC CALC
C4: REBATE TO FOC CALCULATION SHEET
C6: Outlet Name: | E6: =INDEX!C3 -> Outlet Name | I6: Area: | J6: =INDEX!C9 -> Area
C7: Legal Name: | E7: =INDEX!C5 -> Outlet Company Limited | I7: BDE: | J7: =INDEX!C7 -> Name of BDE
C8: Type of Contract | E8: =INDEX!C21 -> Marketing Contract & Yearly Contract
C9: Contract Period: | E9: =INDEX!C19 -> 01 Jan 26 - 31 Dec 26
E11: Contract Period : | G11: =INDEX!C19 -> 01 Jan 26 - 31 Dec 26
E13: Claim Period : | G13: {=IF(COUNTIF(C15:C25,TRUE)+COUNTIF(I15:I25,TRUE)=0,"",TEXT(MIN(IF(C15:C25=TRUE,D15:D25),IF(I15:I25=TRUE,J15:J25)),"mmm yy")&IF(COUNTIF(C15:C25,TRUE)+COUNTIF(I15:I25,TRUE)=1,""," - "&TEXT(MAX(IF(C15:C25=TRUE,D15:D25),IF(I15:I25=TRUE,J15:J25)),"mmm yy")))}
P14: DO NOT DELETE
C15: FALSE | D15: 46023 | F15: =IF(C15=TRUE,'01'!$T$3,0) -> 0 | I15: FALSE | J15: 46204 | L15: =IF(I15=TRUE,'07'!$T$3,0) -> 0
P16: FALSE | Q16: FALSE
C17: FALSE | D17: 46054 | F17: =IF(C17=TRUE,'02'!$T$3,0) -> 0 | I17: FALSE | J17: 46235 | L17: =IF(I17=TRUE,'08'!$T$3,0) -> 0
P18: FALSE | Q18: FALSE
C19: FALSE | D19: 46082 | F19: =IF(C19=TRUE,'03'!$T$3,0) -> 0 | I19: FALSE | J19: 46266 | L19: =IF(I19=TRUE,'09'!$T$3,0) -> 0
P20: FALSE | Q20: FALSE
C21: FALSE | D21: 46113 | F21: =IF(C21=TRUE,'04'!$T$3,0) -> 0 | I21: FALSE | J21: 46296 | L21: =IF(I21=TRUE,'10'!$T$3,0) -> 0
C23: FALSE | D23: 46143 | F23: =IF(C23=TRUE,'05'!$T$3,0) -> 0 | I23: FALSE | J23: 46327 | L23: =IF(I23=TRUE,'11'!$T$3,0) -> 0 | P23: FALSE | Q23: FALSE
C25: FALSE | D25: 46174 | F25: =IF(C25=TRUE,'06'!$T$3,0) -> 0 | I25: FALSE | J25: 46357 | L25: =IF(I25=TRUE,'12'!$T$3,0) -> 0 | P25: FALSE | Q25: FALSE
I27: CLAIMABLE VALUE | L27: =SUM(F15:F25,L15:L25) -> 0 | P27: FALSE | Q27: FALSE
D30: FOC VALUE CALCULATION
J32: INPUT PRICE/BTL HERE
C33: INVENTORY ID. | E33: PRODUCT | H33: SIZE | J33: UNIT PRICE | K33: BTL | L33: VALUE (THB)
C34: =_xlfn.XLOOKUP(E34,MAPPING!G:G,MAPPING!B:B,"",) -> 0 | H34: =_xlfn.XLOOKUP(E34,MAPPING!G:G,MAPPING!H:H,"",) -> 0 | J34: =_xlfn.XLOOKUP(C34,MAPPING!B:B,MAPPING!M:M,"",) | L34: =IFERROR(K34*J34,"")
C35: =_xlfn.XLOOKUP(E35,MAPPING!G:G,MAPPING!B:B,"",) -> 0 | H35: =_xlfn.XLOOKUP(E35,MAPPING!G:G,MAPPING!H:H,"",) -> 0 | J35: =_xlfn.XLOOKUP(C35,MAPPING!B:B,MAPPING!M:M,"",) | L35: =IFERROR(K35*J35,"")
C36: =_xlfn.XLOOKUP(E36,MAPPING!G:G,MAPPING!B:B,"",) -> 0 | H36: =_xlfn.XLOOKUP(E36,MAPPING!G:G,MAPPING!H:H,"",) -> 0 | J36: =_xlfn.XLOOKUP(C36,MAPPING!B:B,MAPPING!M:M,"",) | L36: =IFERROR(K36*J36,"")
C37: =_xlfn.XLOOKUP(E37,MAPPING!G:G,MAPPING!B:B,"",) -> 0 | H37: =_xlfn.XLOOKUP(E37,MAPPING!G:G,MAPPING!H:H,"",) -> 0 | J37: =_xlfn.XLOOKUP(C37,MAPPING!B:B,MAPPING!M:M,"",) | L37: =IFERROR(K37*J37,"")
C38: =_xlfn.XLOOKUP(E38,MAPPING!G:G,MAPPING!B:B,"",) -> 0 | H38: =_xlfn.XLOOKUP(E38,MAPPING!G:G,MAPPING!H:H,"",) -> 0 | J38: =_xlfn.XLOOKUP(C38,MAPPING!B:B,MAPPING!M:M,"",) | L38: =IFERROR(K38*J38,"")
C39: =_xlfn.XLOOKUP(E39,MAPPING!G:G,MAPPING!B:B,"",) -> 0 | H39: =_xlfn.XLOOKUP(E39,MAPPING!G:G,MAPPING!H:H,"",) -> 0 | J39: =_xlfn.XLOOKUP(C39,MAPPING!B:B,MAPPING!M:M,"",) | L39: =IFERROR(K39*J39,"")
C40: =_xlfn.XLOOKUP(E40,MAPPING!G:G,MAPPING!B:B,"",) -> 0 | H40: =_xlfn.XLOOKUP(E40,MAPPING!G:G,MAPPING!H:H,"",) -> 0 | J40: =_xlfn.XLOOKUP(C40,MAPPING!B:B,MAPPING!M:M,"",) | L40: =IFERROR(K40*J40,"")
C41: =_xlfn.XLOOKUP(E41,MAPPING!G:G,MAPPING!B:B,"",) -> 0 | H41: =_xlfn.XLOOKUP(E41,MAPPING!G:G,MAPPING!H:H,"",) -> 0 | J41: =_xlfn.XLOOKUP(C41,MAPPING!B:B,MAPPING!M:M,"",) | L41: =IFERROR(K41*J41,"")
C42: =_xlfn.XLOOKUP(E42,MAPPING!G:G,MAPPING!B:B,"",) -> 0 | H42: =_xlfn.XLOOKUP(E42,MAPPING!G:G,MAPPING!H:H,"",) -> 0 | J42: =_xlfn.XLOOKUP(C42,MAPPING!B:B,MAPPING!M:M,"",) | L42: =IFERROR(K42*J42,"")
C43: =_xlfn.XLOOKUP(E43,MAPPING!G:G,MAPPING!B:B,"",) -> 0 | H43: =_xlfn.XLOOKUP(E43,MAPPING!G:G,MAPPING!H:H,"",) -> 0 | J43: =_xlfn.XLOOKUP(C43,MAPPING!B:B,MAPPING!M:M,"",) | L43: =IFERROR(K43*J43,"")
C44: =_xlfn.XLOOKUP(E44,MAPPING!G:G,MAPPING!B:B,"",) -> 0 | H44: =_xlfn.XLOOKUP(E44,MAPPING!G:G,MAPPING!H:H,"",) -> 0 | J44: =_xlfn.XLOOKUP(C44,MAPPING!B:B,MAPPING!M:M,"",) | L44: =IFERROR(K44*J44,"")
C45: =_xlfn.XLOOKUP(E45,MAPPING!G:G,MAPPING!B:B,"",) -> 0 | H45: =_xlfn.XLOOKUP(E45,MAPPING!G:G,MAPPING!H:H,"",) -> 0 | J45: =_xlfn.XLOOKUP(C45,MAPPING!B:B,MAPPING!M:M,"",) | L45: =IFERROR(K45*J45,"")
... C48: =_xlfn.XLOOKUP(E48,MAPPING!G:G,MAPPING!B:B,"",) -> 0 | H48: =_xlfn.XLOOKUP(E48,MAPPING!G:G,MAPPING!H:H,"",) -> 0 | J48: =_xlfn.XLOOKUP(C48,MAPPING!B:B,MAPPING!M:M,"",) | L48: =IFERROR(K48*J48,"")
C49: TOTAL | K49: =SUM(K34:K48) -> 0 | L49: =SUM(L34:L48) -> 0
I51: CLAIMABLE VALUE | L51: =L27 -> 0
I52: ACTUAL CLAIM | L52: =L49 -> 0
I53: DIFFERENCE | L53: =L51-L52 -> 0

Sheet WHOLESALE
B1: Outlet Rebate Calculation Form
B2: Outlet Name: | C2: =IF(INDEX!C3="","",INDEX!C3) -> Outlet Name | E2: Area: | F2: =IF(INDEX!C9="","",INDEX!C9) -> Area
B4: Legal Name: | C4: =IF(INDEX!C5="","",INDEX!C5) -> Outlet Company Limited | E4: Agent: | F4: =IF(INDEX!C11="","",INDEX!C11) -> Agent name
B6: BDE: | C6: =IF(INDEX!C7="","",INDEX!C7) -> Name of BDE | E6: Supervisor: | F6: =IF(INDEX!C13="","",INDEX!C13) -> Manager Name
B10: *To Add other wholesaler, please type in the last line | D10: =SUBTOTAL(9, D12:D59) -> 0 | E10: =SUBTOTAL(9, E12:E59) -> 0 | F10: =SUBTOTAL(9, F12:F59) -> 0
B11: Region | C11: WHOLESALER | D11: Volume BTLS | E11: Value INC VAT | F11: Value EX VAT | K11: Sheet | L11: Code | M11: Principle | N11: Category | O11: Brand | P11: Brand Code | Q11: Product | R11: Size | S11: Packing | T11: Wholesaler | U11: Price Inc. VAT | V11: Price Ex. VAT | W11: x | X11: Vol. (Btls.) | Y11: x | Z11: Rebate (%) | AA11: x | AB11: Total Price Inc. VAT | AC11: Total Price ex. VAT | AD11: Total Rebate
B12: BANGKOK | C12: Asia Liqour | D12: =IF(SUMIF($T:$T, C12, $X:$X)=0, "", SUMIF($T:$T, C12, $X:$X)) | E12: =IF(SUMIF($T:$T, C12, $U:$U)=0, "", SUMIF($T:$T, C12, $U:$U)) | F12: =IF(SUMIF($T:$T, C12, $V:$V)=0, "", SUMIF($T:$T, C12, $V:$V)) | K12: 1 | L12: {='01'!B13:T365} -> 04-SPWHI-07007491 | M12: TEG | N12: Single Malt Scotch | O12: The Macallan | P12: MAC | Q12: The Macallan Sherry Oak 12YO | R12: 700ml | S12: 12 | T12: 0 | U12: 0 | V12: 0 | W12: 0 | X12: 0 | Y12: 0 | Z12: 0 | AA12: 0 | AB12: 0 | AC12: 0 | AD12: 0
B13: BANGKOK | C13: Boozia | D13: =IF(SUMIF($T:$T, C13, $X:$X)=0, "", SUMIF($T:$T, C13, $X:$X)) | E13: =IF(SUMIF($T:$T, C13, $U:$U)=0, "", SUMIF($T:$T, C13, $U:$U)) | F13: =IF(SUMIF($T:$T, C13, $V:$V)=0, "", SUMIF($T:$T, C13, $V:$V)) | K13: 1 | L13: 04-SPWHI-07017065 | M13: TEG | N13: Single Malt Scotch | O13: The Macallan | P13: MAC | Q13: The Macallan Sherry Oak 18YO | R13: 700ml | S13: 6 | T13: 0 | U13: 0 | V13: 0 | W13: 0 | X13: 0 | Y13: 0 | Z13: 0 | AA13: 0 | AB13: 0 | AC13: 0 | AD13: 0
B14: BANGKOK | C14: Cherry Kansura | D14: =IF(SUMIF($T:$T, C14, $X:$X)=0, "", SUMIF($T:$T, C14, $X:$X)) | E14: =IF(SUMIF($T:$T, C14, $U:$U)=0, "", SUMIF($T:$T, C14, $U:$U)) | F14: =IF(SUMIF($T:$T, C14, $V:$V)=0, "", SUMIF($T:$T, C14, $V:$V)) | K14: 1 | L14: 04-SPWHI-07006031 | M14: TEG | N14: Single Malt Scotch | O14: The Macallan | P14: MAC | Q14: The Macallan Sherry Oak 25YO | R14: 700ml | S14: 3 | T14: 0 | U14: 0 | V14: 0 | W14: 0 | X14: 0 | Y14: 0 | Z14: 0 | AA14: 0 | AB14: 0 | AC14: 0 | AD14: 0
B15: BANGKOK | C15: Charoenchai | D15: =IF(SUMIF($T:$T, C15, $X:$X)=0, "", SUMIF($T:$T, C15, $X:$X)) | E15: =IF(SUMIF($T:$T, C15, $U:$U)=0, "", SUMIF($T:$T, C15, $U:$U)) | F15: =IF(SUMIF($T:$T, C15, $V:$V)=0, "", SUMIF($T:$T, C15, $V:$V)) | K15: 1 | L15: 04-SPWHI-07006048 | M15: TEG | N15: Single Malt Scotch | O15: The Macallan | P15: MAC | Q15: The Macallan Sherry Oak 30YO | R15: 700ml | S15: 3 | T15: 0 | U15: 0 | V15: 0 | W15: 0 | X15: 0 | Y15: 0 | Z15: 0 | AA15: 0 | AB15: 0 | AC15: 0 | AD15: 0
B16: BANGKOK | C16: CN Liqueur | D16: =IF(SUMIF($T:$T, C16, $X:$X)=0, "", SUMIF($T:$T, C16, $X:$X)) | E16: =IF(SUMIF($T:$T, C16, $U:$U)=0, "", SUMIF($T:$T, C16, $U:$U)) | F16: =IF(SUMIF($T:$T, C16, $V:$V)=0, "", SUMIF($T:$T, C16, $V:$V)) | K16: 1 | L16: 04-SPWHI-07003009 | M16: TEG | N16: Single Malt Scotch | O16: The Macallan | P16: MAC | Q16: The Macallan Double Cask 12YO | R16: 700ml | S16: 12 | T16: 0 | U16: 0 | V16: 0 | W16: 0 | X16: 0 | Y16: 0 | Z16: 0 | AA16: 0 | AB16: 0 | AC16: 0 | AD16: 0
B17: BANGKOK | C17: Direct Alchemy | D17: =IF(SUMIF($T:$T, C17, $X:$X)=0, "", SUMIF($T:$T, C17, $X:$X)) | E17: =IF(SUMIF($T:$T, C17, $U:$U)=0, "", SUMIF($T:$T, C17, $U:$U)) | F17: =IF(SUMIF($T:$T, C17, $V:$V)=0, "", SUMIF($T:$T, C17, $V:$V)) | K17: 1 | L17: 04-SPWHI-07007700 | M17: TEG | N17: Single Malt Scotch | O17: The Macallan | P17: MAC | Q17: The Macallan Double Cask 15YO | R17: 700ml | S17: 6 | T17: 0 | U17: 0 | V17: 0 | W17: 0 | X17: 0 | Y17: 0 | Z17: 0 | AA17: 0 | AB17: 0 | AC17: 0 | AD17: 0
B18: BANGKOK | C18: Den Udom | D18: =IF(SUMIF($T:$T, C18, $X:$X)=0, "", SUMIF($T:$T, C18, $X:$X)) | E18: =IF(SUMIF($T:$T, C18, $U:$U)=0, "", SUMIF($T:$T, C18, $U:$U)) | F18: =IF(SUMIF($T:$T, C18, $V:$V)=0, "", SUMIF($T:$T, C18, $V:$V)) | K18: 1 | L18: 04-SPWHI-07009254 | M18: TEG | N18: Single Malt Scotch | O18: The Macallan | P18: MAC | Q18: The Macallan Double Cask 18YO | R18: 700ml | S18: 6 | T18: 0 | U18: 0 | V18: 0 | W18: 0 | X18: 0 | Y18: 0 | Z18: 0 | AA18: 0 | AB18: 0 | AC18: 0 | AD18: 0
B19: BANGKOK | C19: Happy Goods | D19: =IF(SUMIF($T:$T, C19, $X:$X)=0, "", SUMIF($T:$T, C19, $X:$X)) | E19: =IF(SUMIF($T:$T, C19, $U:$U)=0, "", SUMIF($T:$T, C19, $U:$U)) | F19: =IF(SUMIF($T:$T, C19, $V:$V)=0, "", SUMIF($T:$T, C19, $V:$V)) | K19: 1 | L19: 04-SPWHI-07000311 | M19: TEG | N19: Single Malt Scotch | O19: The Macallan | P19: MAC | Q19: The Macallan Double Cask 30YO | R19: 700ml | S19: 3 | T19: 0 | U19: 0 | V19: 0 | W19: 0 | X19: 0 | Y19: 0 | Z19: 0 | AA19: 0 | AB19: 0 | AC19: 0 | AD19: 0
B20: BANGKOK | C20: Happy Spirit | D20: =IF(SUMIF($T:$T, C20, $X:$X)=0, "", SUMIF($T:$T, C20, $X:$X)) | E20: =IF(SUMIF($T:$T, C20, $U:$U)=0, "", SUMIF($T:$T, C20, $U:$U)) | F20: =IF(SUMIF($T:$T, C20, $V:$V)=0, "", SUMIF($T:$T, C20, $V:$V)) | K20: 1 | L20: 04-SPWHI-07000796 | M20: TEG | N20: Single Malt Scotch | O20: The Macallan | P20: MAC | Q20: The Macallan Triple Cask 12YO | R20: 700ml | S20: 12 | T20: 0 | U20: 0 | V20: 0 | W20: 0 | X20: 0 | Y20: 0 | Z20: 0 | AA20: 0 | AB20: 0 | AC20: 0 | AD20: 0
B21: BANGKOK | C21: King Store | D21: =IF(SUMIF($T:$T, C21, $X:$X)=0, "", SUMIF($T:$T, C21, $X:$X)) | E21: =IF(SUMIF($T:$T, C21, $U:$U)=0, "", SUMIF($T:$T, C21, $U:$U)) | F21: =IF(SUMIF($T:$T, C21, $V:$V)=0, "", SUMIF($T:$T, C21, $V:$V)) | K21: 1 | L21: 04-24HMN-07002650 | M21: TEG | N21: Single Malt Scotch | O21: The Macallan | P21: MAC | Q21: The Macallan Harmony Vibrant Oak | R21: 700ml | S21: 6 | T21: 0 | U21: 0 | V21: 0 | W21: 0 | X21: 0 | Y21: 0 | Z21: 0 | AA21: 0 | AB21: 0 | AC21: 0 | AD21: 0
B22: BANGKOK | C22: Mongkol Liquor | D22: =IF(SUMIF($T:$T, C22, $X:$X)=0, "", SUMIF($T:$T, C22, $X:$X)) | E22: =IF(SUMIF($T:$T, C22, $U:$U)=0, "", SUMIF($T:$T, C22, $U:$U)) | F22: =IF(SUMIF($T:$T, C22, $V:$V)=0, "", SUMIF($T:$T, C22, $V:$V)) | K22: 1 | L22: 04-23WHI-07002322 | M22: TEG | N22: Single Malt Scotch | O22: The Macallan | P22: MAC | Q22: The Macallan Harmony Collection Amber Meadow | R22: 700ml | S22: 12 | T22: 0 | U22: 0 | V22: 0 | W22: 0 | X22: 0 | Y22: 0 | Z22: 0 | AA22: 0 | AB22: 0 | AC22: 0 | AD22: 0
B23: BANGKOK | C23: Mercantile | D23: =IF(SUMIF($T:$T, C23, $X:$X)=0, "", SUMIF($T:$T, C23, $X:$X)) | E23: =IF(SUMIF($T:$T, C23, $U:$U)=0, "", SUMIF($T:$T, C23, $U:$U)) | F23: =IF(SUMIF($T:$T, C23, $V:$V)=0, "", SUMIF($T:$T, C23, $V:$V)) | K23: 1 | L23: 04-SPWHI-07000557 | M23: TEG | N23: Single Malt Scotch | O23: The Macallan | P23: MAC | Q23: The Macallan Harmony Collection | R23: 700ml | S23: 6 | T23: 0 | U23: 0 | V23: 0 | W23: 0 | X23: 0 | Y23: 0 | Z23: 0 | AA23: 0 | AB23: 0 | AC23: 0 | AD23: 0
B24: BANGKOK | C24: P.B. Liqueur | D24: =IF(SUMIF($T:$T, C24, $X:$X)=0, "", SUMIF($T:$T, C24, $X:$X)) | E24: =IF(SUMIF($T:$T, C24, $U:$U)=0, "", SUMIF($T:$T, C24, $U:$U)) | F24: =IF(SUMIF($T:$T, C24, $V:$V)=0, "", SUMIF($T:$T, C24, $V:$V)) | K24: 1 | L24: 04-SPWHI-07001226 | M24: TEG | N24: Single Malt Scotch | O24: The Macallan | P24: MAC | Q24: The Macallan Harmony Collection Intense Arabica | R24: 700ml | S24: 6 | T24: 0 | U24: 0 | V24: 0 | W24: 0 | X24: 0 | Y24: 0 | Z24: 0 | AA24: 0 | AB24: 0 | AC24: 0 | AD24: 0
... B73: SOUTH | C73: Trung Suratip | D73: =IF(SUMIF($T:$T, C73, $X:$X)=0, "", SUMIF($T:$T, C73, $X:$X)) | E73: =IF(SUMIF($T:$T, C73, $U:$U)=0, "", SUMIF($T:$T, C73, $U:$U)) | F73: =IF(SUMIF($T:$T, C73, $V:$V)=0, "", SUMIF($T:$T, C73, $V:$V)) | K73: 1 | L73: 23-SPWHI-07000197 | M73: Proximo | N73: Irish Whiskey | O73: Bushmills | P73: BUM | Q73: Bushmills Single Malt 12YO | R73: 700ml | S73: 6 | T73: 0 | U73: 0 | V73: 0 | W73: 0 | X73: 0 | Y73: 0 | Z73: 0 | AA73: 0 | AB73: 0 | AC73: 0 | AD73: 0
K74: 1 | L74: 23-SPWHI-07005022 | M74: Proximo | N74: Irish Whiskey | O74: Bushmills | P74: BUM | Q74: Bushmills Single Malt 16YO | R74: 700ml | S74: 6 | T74: 0 | U74: 0 | V74: 0 | W74: 0 | X74: 0 | Y74: 0 | Z74: 0 | AA74: 0 | AB74: 0 | AC74: 0 | AD74: 0
K75: 1 | L75: 23-SPWHI-07008268 | M75: Proximo | N75: Irish Whiskey | O75: Bushmills | P75: BUM | Q75: Bushmills Single Malt 21YO | R75: 700ml | S75: 6 | T75: 0 | U75: 0 | V75: 0 | W75: 0 | X75: 0 | Y75: 0 | Z75: 0 | AA75: 0 | AB75: 0 | AC75: 0 | AD75: 0
K76: 1 | L76: 47-SPWHI-07000010 | M76: Proximo | N76: Irish Whiskey | O76: The Sexton | P76: TST | Q76: Sexton Single Malt | R76: 700ml | S76: 6 | T76: 0 | U76: 0 | V76: 0 | W76: 0 | X76: 0 | Y76: 0 | Z76: 0 | AA76: 0 | AB76: 0 | AC76: 0 | AD76: 0
K77: 1 | L77: 37-SPWHI-07003251 | M77: Campari | N77: American Whiskey | O77: Wild Turkey | P77: WTK | Q77: Wild Turkey Aged 8 YO | R77: 700ml | S77: 12 | T77: 0 | U77: 0 | V77: 0 | W77: 0 | X77: 0 | Y77: 0 | Z77: 0 | AA77: 0 | AB77: 0 | AC77: 0 | AD77: 0
K78: 1 | L78: 37-SPWHI-07507508 | M78: Campari | N78: American Whiskey | O78: Wild Turkey | P78: WTK | Q78: Wild Turkey 101 Bourbon | R78: 750ml | S78: 12 | T78: 0 | U78: 0 | V78: 0 | W78: 0 | X78: 0 | Y78: 0 | Z78: 0 | AA78: 0 | AB78: 0 | AC78: 0 | AD78: 0
K79: 1 | L79: 37-SPWHI-07507503 | M79: Campari | N79: American Whiskey | O79: Wild Turkey | P79: WTK | Q79: Wild Turkey Bourbon 750ml | R79: 750ml | S79: 12 | T79: 0 | U79: 0 | V79: 0 | W79: 0 | X79: 0 | Y79: 0 | Z79: 0 | AA79: 0 | AB79: 0 | AC79: 0 | AD79: 0
K80: 1 | L80: 37-SPWHI-10001006 | M80: Campari | N80: American Whiskey | O80: Wild Turkey | P80: WTK | Q80: Wild Turkey Bourbon 1L | R80: 1000ml | S80: 12 | T80: 0 | U80: 0 | V80: 0 | W80: 0 | X80: 0 | Y80: 0 | Z80: 0 | AA80: 0 | AB80: 0 | AC80: 0 | AD80: 0
K81: 1 | L81: 37-SPWHI-07007019 | M81: Campari | N81: American Whiskey | O81: Wild Turkey | P81: WTK | Q81: Wild Turkey Rye 40.5% 700ml | R81: 700ml | S81: 6 | T81: 0 | U81: 0 | V81: 0 | W81: 0 | X81: 0 | Y81: 0 | Z81: 0 | AA81: 0 | AB81: 0 | AC81: 0 | AD81: 0
K82: 1 | L82: 37-SPWHI-07500229 | M82: Campari | N82: American Whiskey | O82: Wild Turkey | P82: WTK | Q82: Wild Turkey Rare Breed Bourbon 54.1% | R82: 750ml | S82: 6 | T82: 0 | U82: 0 | V82: 0 | W82: 0 | X82: 0 | Y82: 0 | Z82: 0 | AA82: 0 | AB82: 0 | AC82: 0 | AD82: 0
K83: 1 | L83: 37-SPWHI-07003268 | M83: Campari | N83: American Whiskey | O83: Wild Turkey | P83: WTK | Q83: Wild Turkey Aged 12 Years GB | R83: 700ml | S83: 6 | T83: 0 | U83: 0 | V83: 0 | W83: 0 | X83: 0 | Y83: 0 | Z83: 0 | AA83: 0 | AB83: 0 | AC83: 0 | AD83: 0
K84: 1 | L84: 37-SPLIQ-07507506 | M84: Campari | N84: American Whiskey | O84: Wild Turkey | P84: WTK | Q84: Wild Turkey American Honey 35.5% | R84: 750ml | S84: 12 | T84: 0 | U84: 0 | V84: 0 | W84: 0 | X84: 0 | Y84: 0 | Z84: 0 | AA84: 0 | AB84: 0 | AC84: 0 | AD84: 0
K85: 1 | L85: 37-WTWHI-07507507 | M85: Campari | N85: American Whiskey | O85: Wild Turkey | P85: WTK | Q85: Wild Turkey Kentucky Spirit Single Barrel | R85: 750ml | S85: 6 | T85: 0 | U85: 0 | V85: 0 | W85: 0 | X85: 0 | Y85: 0 | Z85: 0 | AA85: 0 | AB85: 0 | AC85: 0 | AD85: 0
... K336: 1 | L336: 29-SPGIN-07006351 | M336: Remy Cointreau | N336: Gin | O336: Botanist | P336: BOT | Q336: The Botanist Islay Dry Gin (Gift Box) | R336: 700ml | S336: 4 | T336: 0 | U336: 0 | V336: 0 | W336: 0 | X336: 0 | Y336: 0 | Z336: 0 | AA336: 0 | AB336: 0 | AC336: 0 | AD336: 0
K337: 1 | L337: 31-SPMIX-1450PACK | M337: Campari | N337: Liqueur | O337: Aperol/Cinzano | Q337: Aperol + Cinzano Prosecco | R337: 1450ml | S337: 3 | T337: 0 | U337: 0 | V337: 0 | W337: 0 | X337: 0 | Y337: 0 | Z337: 0 | AA337: 0 | AB337: 0 | AC337: 0 | AD337: 0
K338: 1 | L338: 31-SPPAC-07000575 | M338: Campari | N338: Liqueur | O338: Aperol | P338: APR | Q338: Aperol Glass Set | R338: 700ml | S338: 5 | T338: 0 | U338: 0 | V338: 0 | W338: 0 | X338: 0 | Y338: 0 | Z338: 0 | AA338: 0 | AB338: 0 | AC338: 0 | AD338: 0
K339: 1 | L339: 32-06LIQ-05001051 | M339: Campari | N339: Liqueur | O339: Campari | P339: CAM | Q339: Campari Negroni Liqueur | R339: 500ml | S339: 6 | T339: 0 | U339: 0 | V339: 0 | W339: 0 | X339: 0 | Y339: 0 | Z339: 0 | AA339: 0 | AB339: 0 | AC339: 0 | AD339: 0
K340: 1 | L340: 32-06LIQ-07501402 | M340: Campari | N340: Liqueur | O340: Campari | P340: CAM | Q340: Campari Bitter 750 ml | R340: 750ml | S340: 6 | T340: 0 | U340: 0 | V340: 0 | W340: 0 | X340: 0 | Y340: 0 | Z340: 0 | AA340: 0 | AB340: 0 | AC340: 0 | AD340: 0
K341: 1 | L341: 32-SPPAC-07509002 | M341: Campari | N341: Liqueur | O341: Campari | P341: CAM | Q341: Campari Negroni Set | R341: 2250ml | S341: 4 | T341: 0 | U341: 0 | V341: 0 | W341: 0 | X341: 0 | Y341: 0 | Z341: 0 | AA341: 0 | AB341: 0 | AC341: 0 | AD341: 0
K342: 1 | L342: 33-SPGIN-07502000 | M342: Campari | N342: Gin | O342: Bulldog | P342: BUL | Q342: Bulldog London Dry Gin 750 ml | R342: 750ml | S342: 6 | T342: 0 | U342: 0 | V342: 0 | W342: 0 | X342: 0 | Y342: 0 | Z342: 0 | AA342: 0 | AB342: 0 | AC342: 0 | AD342: 0
K343: 1 | L343: 33-SPPAC-07506102 | M343: Campari | N343: Gin | O343: Bulldog | P343: BUL | Q343: Bulldog Gin Glass Set | R343: 750ml | S343: 6 | T343: 0 | U343: 0 | V343: 0 | W343: 0 | X343: 0 | Y343: 0 | Z343: 0 | AA343: 0 | AB343: 0 | AC343: 0 | AD343: 0
...

Sheet SUMMARY
B1: Outlet Rebate Calculation Form
B2: Outlet Name: | C2: =IF(INDEX!C3="","",INDEX!C3) -> Outlet Name | E2: Area: | F2: =IF(INDEX!C9="","",INDEX!C9) -> Area | J2: ='CASH REBATE'!$P$22 -> FALSE | K2: ='CASH REBATE'!$P$24 -> FALSE | L2: ='CASH REBATE'!$P$26 -> FALSE | M2: ='CASH REBATE'!$P$28 -> FALSE | N2: ='CASH REBATE'!$P$30 -> FALSE | O2: ='CASH REBATE'!$P$32 -> FALSE | P2: ='CASH REBATE'!$Q$22 -> FALSE | Q2: ='CASH REBATE'!$Q$24 -> FALSE | R2: ='CASH REBATE'!$Q$26 -> FALSE | S2: ='CASH REBATE'!$Q$28 -> FALSE | T2: ='CASH REBATE'!$Q$30 -> FALSE | U2: ='CASH REBATE'!$Q$32 -> FALSE | V2: ACTUAL VOL BTLS | Y2: ='CASH REBATE'!$P$22 -> FALSE | Z2: ='CASH REBATE'!$P$24 -> FALSE | AA2: ='CASH REBATE'!$P$26 -> FALSE | AB2: ='CASH REBATE'!$P$28 -> FALSE | AC2: ='CASH REBATE'!$P$30 -> FALSE | AD2: ='CASH REBATE'!$P$32 -> FALSE | AE2: ='CASH REBATE'!$Q$22 -> FALSE | AF2: ='CASH REBATE'!$Q$24 -> FALSE | AG2: ='CASH REBATE'!$Q$26 -> FALSE | AH2: ='CASH REBATE'!$Q$28 -> FALSE | AI2: ='CASH REBATE'!$Q$30 -> FALSE | AJ2: ='CASH REBATE'!$Q$32 -> FALSE | AK2: ACTUAL VALUE IN VAT | AN2: ='CASH REBATE'!$P$22 -> FALSE | AO2: ='CASH REBATE'!$P$24 -> FALSE | AP2: ='CASH REBATE'!$P$26 -> FALSE | AQ2: ='CASH REBATE'!$P$28 -> FALSE | AR2: ='CASH REBATE'!$P$30 -> FALSE | AS2: ='CASH REBATE'!$P$32 -> FALSE | AT2: ='CASH REBATE'!$Q$22 -> FALSE | AU2: ='CASH REBATE'!$Q$24 -> FALSE | AV2: ='CASH REBATE'!$Q$26 -> FALSE | AW2: ='CASH REBATE'!$Q$28 -> FALSE | AX2: ='CASH REBATE'!$Q$30 -> FALSE | AY2: ='CASH REBATE'!$Q$32 -> FALSE | AZ2: ACTUAL VALUE EX VAT | BC2: ='CASH REBATE'!$P$22 -> FALSE | BD2: ='CASH REBATE'!$P$24 -> FALSE | BE2: ='CASH REBATE'!$P$26 -> FALSE | BF2: ='CASH REBATE'!$P$28 -> FALSE | BG2: ='CASH REBATE'!$P$30 -> FALSE | BH2: ='CASH REBATE'!$P$32 -> FALSE | BI2: ='CASH REBATE'!$Q$22 -> FALSE | BJ2: ='CASH REBATE'!$Q$24 -> FALSE | BK2: ='CASH REBATE'!$Q$26 -> FALSE | BL2: ='CASH REBATE'!$Q$28 -> FALSE | BM2: ='CASH REBATE'!$Q$30 -> FALSE | BN2: ='CASH REBATE'!$Q$32 -> FALSE | BO2: ACTUAL REBATE VALUE
BQ3: f
B4: Legal Name: | C4: =IF(INDEX!C5="","",INDEX!C5) -> Outlet Company Limited | E4: Agent: | F4: =IF(INDEX!C11="","",INDEX!C11) -> Agent name | I4: ALL PRINCIPLE | J4: =SUM(J12:J394) -> 0 | K4: =SUM(K12:K394) -> 0 | L4: =SUM(L12:L394) -> 0 | M4: =SUM(M12:M394) -> 0 | N4: =SUM(N12:N394) -> 0 | O4: =SUM(O12:O394) -> 10 | P4: =SUM(P12:P394) -> 0 | Q4: =SUM(Q12:Q394) -> 0 | ... W4: =SUM(W12:W394) -> 0 | Y4: =SUM(Y12:Y394) -> 0 | Z4: =SUM(Z12:Z394) -> 0 | AA4: =SUM(AA12:AA394) -> 0 | AB4: =SUM(AB12:AB394) -> 0 | AC4: =SUM(AC12:AC394) -> 0 | AD4: =SUM(AD12:AD394) -> 10700 | AE4: =SUM(AE12:AE394) -> 0 | AF4: =SUM(AF12:AF394) -> 0 | ... AL4: =SUM(AL12:AL394) -> 0 | AN4: =SUM(AN12:AN394) -> 0 | AO4: =SUM(AO12:AO394) -> 0 | AP4: =SUM(AP12:AP394) -> 0 | AQ4: =SUM(AQ12:AQ394) -> 0 | AR4: =SUM(AR12:AR394) -> 0 | AS4: =SUM(AS12:AS394) -> 10000 | AT4: =SUM(AT12:AT394) -> 0 | AU4: =SUM(AU12:AU394) -> 0 | ... BA4: =SUM(BA12:BA394) -> 0 | BC4: =SUM(BC12:BC394) -> 0 | BD4: =SUM(BD12:BD394) -> 0 | BE4: =SUM(BE12:BE394) -> 0 | BF4: =SUM(BF12:BF394) -> 0 | BG4: =SUM(BG12:BG394) -> 0 | BH4: =SUM(BH12:BH394) -> 0 | BI4: =SUM(BI12:BI394) -> 0 | BJ4: =SUM(BJ12:BJ394) -> 0 | ... BO4: =SUM(BO12:BO394) -> 0 | BP4: =SUMIFS($BC4:$BN4,$BC$2:$BN$2,"TRUE") -> 0
B6: BDE: | C6: =IF(INDEX!C7="","",INDEX!C7) -> Name of BDE | E6: Supervisor: | F6: =IF(INDEX!C13="","",INDEX!C13) -> Manager Name | I6: Campari | J6: =SUMIFS(J$12:J$394,$C$12:$C$394,$I$6) -> 0 | K6: =SUMIFS(K$12:K$394,$C$12:$C$394,$I$6) -> 0 | L6: =SUMIFS(L$12:L$394,$C$12:$C$394,$I$6) -> 0 | M6: =SUMIFS(M$12:M$394,$C$12:$C$394,$I$6) -> 0 | N6: =SUMIFS(N$12:N$394,$C$12:$C$394,$I$6) -> 0 | O6: =SUMIFS(O$12:O$394,$C$12:$C$394,$I$6) -> 0 | P6: =SUMIFS(P$12:P$394,$C$12:$C$394,$I$6) -> 0 | Q6: =SUMIFS(Q$12:Q$394,$C$12:$C$394,$I$6) -> 0 | ... U6: =SUMIFS(U$12:U$394,$C$12:$C$394,$I$6) -> 0 | V6: =SUMIFS(V$12:V$394,$C$12:$C$394,$I$8) -> 0 | W6: =SUMIFS(W$12:W$394,$C$12:$C$394,$I$8) -> 0 | Y6: =SUMIFS(Y$12:Y$349,$C$12:$C$349,$I$6) -> 0 | Z6: =SUMIFS(Z$12:Z$349,$C$12:$C$349,$I$6) -> 0 | AA6: =SUMIFS(AA$12:AA$349,$C$12:$C$349,$I$6) -> 0 | AB6: =SUMIFS(AB$12:AB$349,$C$12:$C$349,$I$6) -> 0 | AC6: =SUMIFS(AC$12:AC$349,$C$12:$C$349,$I$6) -> 0 | AD6: =SUMIFS(AD$12:AD$349,$C$12:$C$349,$I$6) -> 0 | AE6: =SUMIFS(AE$12:AE$349,$C$12:$C$349,$I$6) -> 0 | AF6: =SUMIFS(AF$12:AF$349,$C$12:$C$349,$I$6) -> 0 | ... AL6: =SUMIFS(AL$12:AL$349,$C$12:$C$349,$I$6) -> 0 | AN6: =SUMIFS(AN$12:AN$349,$C$12:$C$349,$I$6) -> 0 | AO6: =SUMIFS(AO$12:AO$349,$C$12:$C$349,$I$6) -> 0 | AP6: =SUMIFS(AP$12:AP$349,$C$12:$C$349,$I$6) -> 0 | AQ6: =SUMIFS(AQ$12:AQ$349,$C$12:$C$349,$I$6) -> 0 | AR6: =SUMIFS(AR$12:AR$349,$C$12:$C$349,$I$6) -> 0 | AS6: =SUMIFS(AS$12:AS$349,$C$12:$C$349,$I$6) -> 0 | AT6: =SUMIFS(AT$12:AT$349,$C$12:$C$349,$I$6) -> 0 | AU6: =SUMIFS(AU$12:AU$349,$C$12:$C$349,$I$6) -> 0 | ... BA6: =SUMIFS(BA$12:BA$349,$C$12:$C$349,$I$6) -> 0 | BC6: =SUMIFS(BC$12:BC$394,$C$12:$C$394,$I$8) -> 0 | BD6: =SUMIFS(BD$12:BD$394,$C$12:$C$394,$I$8) -> 0 | BE6: =SUMIFS(BE$12:BE$394,$C$12:$C$394,$I$8) -> 0 | BF6: =SUMIFS(BF$12:BF$394,$C$12:$C$394,$I$8) -> 0 | BG6: =SUMIFS(BG$12:BG$394,$C$12:$C$394,$I$8) -> 0 | BH6: =SUMIFS(BH$12:BH$394,$C$12:$C$394,$I$8) -> 0 | BI6: =SUMIFS(BI$12:BI$394,$C$12:$C$394,$I$8) -> 0 | BJ6: =SUMIFS(BJ$12:BJ$394,$C$12:$C$394,$I$8) -> 0 | ... BO6: =SUMIFS(BO$12:BO$394,$C$12:$C$394,$I$8) -> 0 | BP6: =SUMIFS($BC6:$BN6,$BC$2:$BN$2,"TRUE") -> 0
J10: =SUBTOTAL(9,J13:J354) -> 0 | K10: =SUBTOTAL(9,K13:K354) -> 0 | L10: =SUBTOTAL(9,L13:L354) -> 0 | M10: =SUBTOTAL(9,M13:M354) -> 0 | N10: =SUBTOTAL(9,N13:N354) -> 0 | O10: =SUBTOTAL(9,O13:O354) -> 10 | P10: =SUBTOTAL(9,P13:P354) -> 0 | Q10: =SUBTOTAL(9,Q13:Q354) -> 0 | ... BP10: =SUBTOTAL(9,BP13:BP354) -> 0
B11: Principle | C11: Principle | D11: Category | E11: Brand | F11: Brand Code | G11: Product | H11: Size | I11: Packing | J11: Volume (Bts) | W11: Selected MTH | Y11: Price IN. VAT | AL11: Selected MTH | AN11: Price EX. VAT | BA11: Selected MTH | BC11: Rebate | BP11: Selected MTH
J12: JAN | K12: FEB | L12: MAR | M12: APR | N12: MAY | O12: JUN | P12: JUL | Q12: AUG | R12: SEP | S12: OCT | T12: NOV | U12: DEC | V12: VOL (Bts) | W12: VOL (bts) | X12: x | Y12: JAN | Z12: FEB | AA12: MAR | AB12: APR | AC12: MAY | AD12: JUN | AE12: JUL | AF12: AUG | AG12: SEP | AH12: OCT | AI12: NOV | AJ12: DEC | AK12: Price in VAT | AL12: Price in VAT | AM12: x | AN12: JAN | AO12: FEB | AP12: MAR | AQ12: APR | AR12: MAY | AS12: JUN | AT12: JUL | AU12: AUG | AV12: SEP | AW12: OCT | AX12: NOV | AY12: DEC | AZ12: Price ex VAT | BA12: Price ex VAT | BB12: x | BC12: JAN | BD12: FEB | BE12: MAR | BF12: APR | BG12: MAY | BH12: JUN | BI12: JUL | BJ12: AUG | BK12: SEP | BL12: OCT | BM12: NOV | BN12: DEC | BO12: REBATE | BP12: Amount
B13: {=MAPPING!$B$3:$I$296} -> 04-SPWHI-07007491 | C13: TEG | D13: Single Malt Scotch | E13: The Macallan | F13: MAC | G13: The Macallan Sherry Oak 12YO | H13: 700ml | I13: 12 | J13: ='01'!N13 -> 0 | K13: ='02'!N13 -> 0 | L13: ='03'!N13 -> 0 | M13: ='04'!N13 -> 0 | N13: ='05'!N13 -> 0 | O13: ='06'!N13 -> 0 | P13: ='07'!N13 -> 0 | Q13: ='08'!N13 -> 0 | R13: ='09'!N13 -> 0 | S13: ='10'!N13 -> 0 | T13: ='11'!N13 -> 0 | U13: ='12'!N13 -> 0 | V13: =SUM(J13:U13) -> 0 | W13: =SUMIFS($J13:$U13,$J$2:$U$2,"TRUE") -> 0 | Y13: ='01'!R13 -> 0 | Z13: ='02'!R13 -> 0 | AA13: ='03'!R13 -> 0 | AB13: ='04'!R13 -> 0 | AC13: ='05'!R13 -> 0 | AD13: ='06'!R13 -> 0 | AE13: ='07'!R13 -> 0 | AF13: ='08'!R13 -> 0 | AG13: ='09'!R13 -> 0 | AH13: ='10'!R13 -> 0 | AI13: ='11'!R13 -> 0 | AJ13: ='12'!R13 -> 0 | AK13: =SUM(Y13:AJ13) -> 0 | AL13: =SUMIFS($Y13:$AJ13,$Y$2:$AJ$2,"TRUE") -> 0 | AN13: ='01'!S13 -> 0 | AO13: ='02'!S13 -> 0 | AP13: ='03'!S13 -> 0 | AQ13: ='04'!S13 -> 0 | AR13: ='05'!S13 -> 0 | AS13: ='06'!S13 -> 0 | AT13: ='07'!S13 -> 0 | AU13: ='08'!S13 -> 0 | AV13: ='09'!S13 -> 0 | AW13: ='10'!S13 -> 0 | AX13: ='11'!S13 -> 0 | AY13: ='12'!S13 -> 0 | AZ13: =SUM(AN13:AY13) -> 0 | BA13: =SUMIFS($AN13:$AY13,$AN$2:$AY$2,"TRUE") -> 0 | BC13: ='01'!T13 -> 0 | BD13: ='02'!T13 -> 0 | BE13: ='03'!T13 -> 0 | BF13: ='04'!T13 -> 0 | BG13: ='05'!T13 -> 0 | BH13: ='06'!T13 -> 0 | BI13: ='07'!T13 -> 0 | BJ13: ='08'!T13 -> 0 | BK13: ='09'!T13 -> 0 | BL13: ='10'!T13 -> 0 | BM13: ='11'!T13 -> 0 | BN13: ='12'!T13 -> 0 | BO13: =SUM(BC13:BN13) -> 0 | BP13: =SUMIFS($BC13:$BN13,$BC$2:$BN$2,"TRUE") -> 0
B14: 04-SPWHI-07017065 | C14: TEG | D14: Single Malt Scotch | E14: The Macallan | F14: MAC | G14: The Macallan Sherry Oak 18YO | H14: 700ml | I14: 6 | J14: ='01'!N14 -> 0 | K14: ='02'!N14 -> 0 | L14: ='03'!N14 -> 0 | M14: ='04'!N14 -> 0 | N14: ='05'!N14 -> 0 | O14: ='06'!N14 -> 0 | P14: ='07'!N14 -> 0 | Q14: ='08'!N14 -> 0 | R14: ='09'!N14 -> 0 | S14: ='10'!N14 -> 0 | T14: ='11'!N14 -> 0 | U14: ='12'!N14 -> 0 | V14: =SUM(J14:U14) -> 0 | W14: =SUMIFS($J14:$U14,$J$2:$U$2,"TRUE") -> 0 | Y14: ='01'!R14 -> 0 | Z14: ='02'!R14 -> 0 | AA14: ='03'!R14 -> 0 | AB14: ='04'!R14 -> 0 | AC14: ='05'!R14 -> 0 | AD14: ='06'!R14 -> 0 | AE14: ='07'!R14 -> 0 | AF14: ='08'!R14 -> 0 | AG14: ='09'!R14 -> 0 | AH14: ='10'!R14 -> 0 | AI14: ='11'!R14 -> 0 | AJ14: ='12'!R14 -> 0 | AK14: =SUM(Y14:AJ14) -> 0 | AL14: =SUMIFS($Y14:$AJ14,$Y$2:$AJ$2,"TRUE") -> 0 | AN14: ='01'!S14 -> 0 | AO14: ='02'!S14 -> 0 | AP14: ='03'!S14 -> 0 | AQ14: ='04'!S14 -> 0 | AR14: ='05'!S14 -> 0 | AS14: ='06'!S14 -> 0 | AT14: ='07'!S14 -> 0 | AU14: ='08'!S14 -> 0 | AV14: ='09'!S14 -> 0 | AW14: ='10'!S14 -> 0 | AX14: ='11'!S14 -> 0 | AY14: ='12'!S14 -> 0 | AZ14: =SUM(AN14:AY14) -> 0 | BA14: =SUMIFS($AN14:$AY14,$AN$2:$AY$2,"TRUE") -> 0 | BC14: ='01'!T14 -> 0 | BD14: ='02'!T14 -> 0 | BE14: ='03'!T14 -> 0 | BF14: ='04'!T14 -> 0 | BG14: ='05'!T14 -> 0 | BH14: ='06'!T14 -> 0 | BI14: ='07'!T14 -> 0 | BJ14: ='08'!T14 -> 0 | BK14: ='09'!T14 -> 0 | BL14: ='10'!T14 -> 0 | BM14: ='11'!T14 -> 0 | BN14: ='12'!T14 -> 0 | BO14: =SUM(BC14:BN14) -> 0 | BP14: =SUMIFS($BC14:$BN14,$BC$2:$BN$2,"TRUE") -> 0
B15: 04-SPWHI-07006031 | C15: TEG | D15: Single Malt Scotch | E15: The Macallan | F15: MAC | G15: The Macallan Sherry Oak 25YO | H15: 700ml | I15: 3 | J15: ='01'!N15 -> 0 | K15: ='02'!N15 -> 0 | L15: ='03'!N15 -> 0 | M15: ='04'!N15 -> 0 | N15: ='05'!N15 -> 0 | O15: ='06'!N15 -> 10 | P15: ='07'!N15 -> 0 | Q15: ='08'!N15 -> 0 | R15: ='09'!N15 -> 0 | S15: ='10'!N15 -> 0 | T15: ='11'!N15 -> 0 | U15: ='12'!N15 -> 0 | V15: =SUM(J15:U15) -> 10 | W15: =SUMIFS($J15:$U15,$J$2:$U$2,"TRUE") -> 0 | Y15: ='01'!R15 -> 0 | Z15: ='02'!R15 -> 0 | AA15: ='03'!R15 -> 0 | AB15: ='04'!R15 -> 0 | AC15: ='05'!R15 -> 0 | AD15: ='06'!R15 -> 10700 | AE15: ='07'!R15 -> 0 | AF15: ='08'!R15 -> 0 | AG15: ='09'!R15 -> 0 | AH15: ='10'!R15 -> 0 | AI15: ='11'!R15 -> 0 | AJ15: ='12'!R15 -> 0 | AK15: =SUM(Y15:AJ15) -> 10700 | AL15: =SUMIFS($Y15:$AJ15,$Y$2:$AJ$2,"TRUE") -> 0 | AN15: ='01'!S15 -> 0 | AO15: ='02'!S15 -> 0 | AP15: ='03'!S15 -> 0 | AQ15: ='04'!S15 -> 0 | AR15: ='05'!S15 -> 0 | AS15: ='06'!S15 -> 10000 | AT15: ='07'!S15 -> 0 | AU15: ='08'!S15 -> 0 | AV15: ='09'!S15 -> 0 | AW15: ='10'!S15 -> 0 | AX15: ='11'!S15 -> 0 | AY15: ='12'!S15 -> 0 | AZ15: =SUM(AN15:AY15) -> 10000 | BA15: =SUMIFS($AN15:$AY15,$AN$2:$AY$2,"TRUE") -> 0 | BC15: ='01'!T15 -> 0 | BD15: ='02'!T15 -> 0 | BE15: ='03'!T15 -> 0 | BF15: ='04'!T15 -> 0 | BG15: ='05'!T15 -> 0 | BH15: ='06'!T15 -> 0 | BI15: ='07'!T15 -> 0 | BJ15: ='08'!T15 -> 0 | BK15: ='09'!T15 -> 0 | BL15: ='10'!T15 -> 0 | BM15: ='11'!T15 -> 0 | BN15: ='12'!T15 -> 0 | BO15: =SUM(BC15:BN15) -> 0 | BP15: =SUMIFS($BC15:$BN15,$BC$2:$BN$2,"TRUE") -> 0
B16: 04-SPWHI-07006048 | C16: TEG | D16: Single Malt Scotch | E16: The Macallan | F16: MAC | G16: The Macallan Sherry Oak 30YO | H16: 700ml | I16: 3 | J16: ='01'!N16 -> 0 | K16: ='02'!N16 -> 0 | L16: ='03'!N16 -> 0 | M16: ='04'!N16 -> 0 | N16: ='05'!N16 -> 0 | O16: ='06'!N16 -> 0 | P16: ='07'!N16 -> 0 | Q16: ='08'!N16 -> 0 | R16: ='09'!N16 -> 0 | S16: ='10'!N16 -> 0 | T16: ='11'!N16 -> 0 | U16: ='12'!N16 -> 0 | V16: =SUM(J16:U16) -> 0 | W16: =SUMIFS($J16:$U16,$J$2:$U$2,"TRUE") -> 0 | Y16: ='01'!R16 -> 0 | Z16: ='02'!R16 -> 0 | AA16: ='03'!R16 -> 0 | AB16: ='04'!R16 -> 0 | AC16: ='05'!R16 -> 0 | AD16: ='06'!R16 -> 0 | AE16: ='07'!R16 -> 0 | AF16: ='08'!R16 -> 0 | AG16: ='09'!R16 -> 0 | AH16: ='10'!R16 -> 0 | AI16: ='11'!R16 -> 0 | AJ16: ='12'!R16 -> 0 | AK16: =SUM(Y16:AJ16) -> 0 | AL16: =SUMIFS($Y16:$AJ16,$Y$2:$AJ$2,"TRUE") -> 0 | AN16: ='01'!S16 -> 0 | AO16: ='02'!S16 -> 0 | AP16: ='03'!S16 -> 0 | AQ16: ='04'!S16 -> 0 | AR16: ='05'!S16 -> 0 | AS16: ='06'!S16 -> 0 | AT16: ='07'!S16 -> 0 | AU16: ='08'!S16 -> 0 | AV16: ='09'!S16 -> 0 | AW16: ='10'!S16 -> 0 | AX16: ='11'!S16 -> 0 | AY16: ='12'!S16 -> 0 | AZ16: =SUM(AN16:AY16) -> 0 | BA16: =SUMIFS($AN16:$AY16,$AN$2:$AY$2,"TRUE") -> 0 | BC16: ='01'!T16 -> 0 | BD16: ='02'!T16 -> 0 | BE16: ='03'!T16 -> 0 | BF16: ='04'!T16 -> 0 | BG16: ='05'!T16 -> 0 | BH16: ='06'!T16 -> 0 | BI16: ='07'!T16 -> 0 | BJ16: ='08'!T16 -> 0 | BK16: ='09'!T16 -> 0 | BL16: ='10'!T16 -> 0 | BM16: ='11'!T16 -> 0 | BN16: ='12'!T16 -> 0 | BO16: =SUM(BC16:BN16) -> 0 | BP16: =SUMIFS($BC16:$BN16,$BC$2:$BN$2,"TRUE") -> 0
B17: 04-SPWHI-07003009 | C17: TEG | D17: Single Malt Scotch | E17: The Macallan | F17: MAC | G17: The Macallan Double Cask 12YO | H17: 700ml | I17: 12 | J17: ='01'!N17 -> 0 | K17: ='02'!N17 -> 0 | L17: ='03'!N17 -> 0 | M17: ='04'!N17 -> 0 | N17: ='05'!N17 -> 0 | O17: ='06'!N17 -> 0 | P17: ='07'!N17 -> 0 | Q17: ='08'!N17 -> 0 | R17: ='09'!N17 -> 0 | S17: ='10'!N17 -> 0 | T17: ='11'!N17 -> 0 | U17: ='12'!N17 -> 0 | V17: =SUM(J17:U17) -> 0 | W17: =SUMIFS($J17:$U17,$J$2:$U$2,"TRUE") -> 0 | Y17: ='01'!R17 -> 0 | Z17: ='02'!R17 -> 0 | AA17: ='03'!R17 -> 0 | AB17: ='04'!R17 -> 0 | AC17: ='05'!R17 -> 0 | AD17: ='06'!R17 -> 0 | AE17: ='07'!R17 -> 0 | AF17: ='08'!R17 -> 0 | AG17: ='09'!R17 -> 0 | AH17: ='10'!R17 -> 0 | AI17: ='11'!R17 -> 0 | AJ17: ='12'!R17 -> 0 | AK17: =SUM(Y17:AJ17) -> 0 | AL17: =SUMIFS($Y17:$AJ17,$Y$2:$AJ$2,"TRUE") -> 0 | AN17: ='01'!S17 -> 0 | AO17: ='02'!S17 -> 0 | AP17: ='03'!S17 -> 0 | AQ17: ='04'!S17 -> 0 | AR17: ='05'!S17 -> 0 | AS17: ='06'!S17 -> 0 | AT17: ='07'!S17 -> 0 | AU17: ='08'!S17 -> 0 | AV17: ='09'!S17 -> 0 | AW17: ='10'!S17 -> 0 | AX17: ='11'!S17 -> 0 | AY17: ='12'!S17 -> 0 | AZ17: =SUM(AN17:AY17) -> 0 | BA17: =SUMIFS($AN17:$AY17,$AN$2:$AY$2,"TRUE") -> 0 | BC17: ='01'!T17 -> 0 | BD17: ='02'!T17 -> 0 | BE17: ='03'!T17 -> 0 | BF17: ='04'!T17 -> 0 | BG17: ='05'!T17 -> 0 | BH17: ='06'!T17 -> 0 | BI17: ='07'!T17 -> 0 | BJ17: ='08'!T17 -> 0 | BK17: ='09'!T17 -> 0 | BL17: ='10'!T17 -> 0 | BM17: ='11'!T17 -> 0 | BN17: ='12'!T17 -> 0 | BO17: =SUM(BC17:BN17) -> 0 | BP17: =SUMIFS($BC17:$BN17,$BC$2:$BN$2,"TRUE") -> 0
